Workbook

Sheet ANALISIS
A1: ° | B1: PERSONAJE | C1: base | D1: prioridad | E1: %Aparicion | F1: pos | G1: DifficultyFindPractice | H1: LVL MAX USUARIO | I1: NOTA | J1: Column10 | K1: Column11 | L1: Column12 | M1: Column13 | N1: Column14 | O1: Column15 | P1: Column16 | Q1: Column17 | R1: Column18 | S1: Column19 | T1: Column20
A2: 40 | B2: R.O.B. | C2: =VLOOKUP(B2, PLAYERS!C:E, 3, FALSE) -> 3 | D2: =SUMIF(PLAYERS!C:C, B2, PLAYERS!E:E) -> 40 | F2: 1 | G2: ? | H2: A | I2: Si es
A3: 77 | B3: AEGIS | C3: =VLOOKUP(B3, PLAYERS!C:E, 3, FALSE) -> 10 | D3: =SUMIF(PLAYERS!C:C, B3, PLAYERS!E:E) -> 28 | F3: 2 | G3: EASY | I3: impossible o "hard" de encontrar partida
A4: 59 | B4: Cloud | C4: =VLOOKUP(B4, PLAYERS!C:E, 3, FALSE) -> 25 | D4: =SUMIF(PLAYERS!C:C, B4, PLAYERS!E:E) -> 25 | F4: 3 | G4: EASY | I4: o usuario es level "nivel S or S+"
A5: 42 | B5: Wolf | C5: =VLOOKUP(B5, PLAYERS!C:E, 3, FALSE) -> 24 | D5: =SUMIF(PLAYERS!C:C, B5, PLAYERS!E:E) -> 24 | F5: 4 | G5: HARD | I5: entonces: ,vale la pena estudiar y jugarle
A6: 34 | B6: Diddy Kong | C6: =VLOOKUP(B6, PLAYERS!C:E, 3, FALSE) -> 21 | D6: =SUMIF(PLAYERS!C:C, B6, PLAYERS!E:E) -> 21 | F6: 5 | G6: IMPOSSIBLE
A7: 32 | B7: Ike | C7: =VLOOKUP(B7, PLAYERS!C:E, 3, FALSE) -> 20 | D7: =SUMIF(PLAYERS!C:C, B7, PLAYERS!E:E) -> 20 | F7: 6 | G7: ?
A8: 31 | B8: Snake | C8: =VLOOKUP(B8, PLAYERS!C:E, 3, FALSE) -> 20 | D8: =SUMIF(PLAYERS!C:C, B8, PLAYERS!E:E) -> 20 | F8: 7 | G8: ?
A9: 17 | B9: Zelda | C9: =VLOOKUP(B9, PLAYERS!C:E, 3, FALSE) -> 18 | D9: =SUMIF(PLAYERS!C:C, B9, PLAYERS!E:E) -> 18 | F9: 8 | G9: ?
A10: 72 | B10: Terry | C10: =VLOOKUP(B10, PLAYERS!C:E, 3, FALSE) -> 7 | D10: =SUMIF(PLAYERS!C:C, B10, PLAYERS!E:E) -> 17 | F10: 9 | G10: ?
A11: 71 | B11: Banjo & Kazooie | C11: =VLOOKUP(B11, PLAYERS!C:E, 3, FALSE) -> 16 | D11: =SUMIF(PLAYERS!C:C, B11, PLAYERS!E:E) -> 16 | F11: 10 | G11: NORMAL
A12: 67 | B12: Incineroar | C12: =VLOOKUP(B12, PLAYERS!C:E, 3, FALSE) -> 5 | D12: =SUMIF(PLAYERS!C:C, B12, PLAYERS!E:E) -> 16 | F12: 11 | G12: ?
A13: 61 | B13: Bayonetta | C13: =VLOOKUP(B13, PLAYERS!C:E, 3, FALSE) -> 15 | D13: =SUMIF(PLAYERS!C:C, B13, PLAYERS!E:E) -> 15 | F13: 12 | G13: ?
A14: 39 | B14: Lucario | C14: =VLOOKUP(B14, PLAYERS!C:E, 3, FALSE) -> 14 | D14: =SUMIF(PLAYERS!C:C, B14, PLAYERS!E:E) -> 14 | F14: 13 | G14: ?
A15: 75 | B15: Steve/Alex | C15: =VLOOKUP(B15, PLAYERS!C:E, 3, FALSE) -> 13 | D15: =SUMIF(PLAYERS!C:C, B15, PLAYERS!E:E) -> 13 | F15: 14 | G15: EASY
A16: 64 | B16: Simon | C16: =VLOOKUP(B16, PLAYERS!C:E, 3, FALSE) -> 7 | D16: =SUMIF(PLAYERS!C:C, B16, PLAYERS!E:E) -> 12 | F16: 15 | G16: HARD
A17: 65 | B17: King K. Rool | C17: =VLOOKUP(B17, PLAYERS!C:E, 3, FALSE) -> 10 | D17: =SUMIF(PLAYERS!C:C, B17, PLAYERS!E:E) -> 10 | F17: 16
A18: 27 | B18: Meta Knight | C18: =VLOOKUP(B18, PLAYERS!C:E, 3, FALSE) -> 8 | D18: =SUMIF(PLAYERS!C:C, B18, PLAYERS!E:E) -> 8 | F18: 17
A19: 1 | B19: Mario | C19: =VLOOKUP(B19, PLAYERS!C:E, 3, FALSE) -> 6 | D19: =SUMIF(PLAYERS!C:C, B19, PLAYERS!E:E) -> 6 | F19: 18
A20: 8 | B20: Pikachu | C20: =VLOOKUP(B20, PLAYERS!C:E, 3, FALSE) -> 6 | D20: =SUMIF(PLAYERS!C:C, B20, PLAYERS!E:E) -> 6 | F20: 19
A21: 3 | B21: Link | C21: =VLOOKUP(B21, PLAYERS!C:E, 3, FALSE) -> 5 | D21: =SUMIF(PLAYERS!C:C, B21, PLAYERS!E:E) -> 5 | F21: 20
A22: 25 | B22: Roy | C22: =VLOOKUP(B22, PLAYERS!C:E, 3, FALSE) -> 3 | D22: =SUMIF(PLAYERS!C:C, B22, PLAYERS!E:E) -> 3 | F22: 21
A23: 36 | B23: Sonic | C23: =VLOOKUP(B23, PLAYERS!C:E, 3, FALSE) -> 2 | D23: =SUMIF(PLAYERS!C:C, B23, PLAYERS!E:E) -> 2 | F23: 22
A24: 2 | B24: Donkey Kong | C24: =VLOOKUP(B24, PLAYERS!C:E, 3, FALSE) -> #N/A | D24: =SUMIF(PLAYERS!C:C, B24, PLAYERS!E:E) -> 0 | F24: 23
A25: 4 | B25: Samus | C25: =VLOOKUP(B25, PLAYERS!C:E, 3, FALSE) -> #N/A | D25: =SUMIF(PLAYERS!C:C, B25, PLAYERS!E:E) -> 0 | F25: 24
A26: 5 | B26: Yoshi | C26: =VLOOKUP(B26, PLAYERS!C:E, 3, FALSE) -> #N/A | D26: =SUMIF(PLAYERS!C:C, B26, PLAYERS!E:E) -> 0
A27: 6 | B27: Kirby | C27: =VLOOKUP(B27, PLAYERS!C:E, 3, FALSE) -> #N/A | D27: =SUMIF(PLAYERS!C:C, B27, PLAYERS!E:E) -> 0
A28: 7 | B28: Fox | C28: =VLOOKUP(B28, PLAYERS!C:E, 3, FALSE) -> #N/A | D28: =SUMIF(PLAYERS!C:C, B28, PLAYERS!E:E) -> 0
A29: 9 | B29: Luigi | C29: =VLOOKUP(B29, PLAYERS!C:E, 3, FALSE) -> #N/A | D29: =SUMIF(PLAYERS!C:C, B29, PLAYERS!E:E) -> 0
A30: 10 | B30: Ness | C30: =VLOOKUP(B30, PLAYERS!C:E, 3, FALSE) -> #N/A | D30: =SUMIF(PLAYERS!C:C, B30, PLAYERS!E:E) -> 0
A31: 11 | B31: Captain Falcon | C31: =VLOOKUP(B31, PLAYERS!C:E, 3, FALSE) -> #N/A | D31: =SUMIF(PLAYERS!C:C, B31, PLAYERS!E:E) -> 0
A32: 12 | B32: Jigglypuff | C32: =VLOOKUP(B32, PLAYERS!C:E, 3, FALSE) -> #N/A | D32: =SUMIF(PLAYERS!C:C, B32, PLAYERS!E:E) -> 0
A33: 13 | B33: Peach | C33: =VLOOKUP(B33, PLAYERS!C:E, 3, FALSE) -> #N/A | D33: =SUMIF(PLAYERS!C:C, B33, PLAYERS!E:E) -> 0
A34: 14 | B34: Bowser | C34: =VLOOKUP(B34, PLAYERS!C:E, 3, FALSE) -> #N/A | D34: =SUMIF(PLAYERS!C:C, B34, PLAYERS!E:E) -> 0
A35: 15 | B35: Ice Climbers | C35: =VLOOKUP(B35, PLAYERS!C:E, 3, FALSE) -> #N/A | D35: =SUMIF(PLAYERS!C:C, B35, PLAYERS!E:E) -> 0
A36: 16 | B36: Sheik | C36: =VLOOKUP(B36, PLAYERS!C:E, 3, FALSE) -> #N/A | D36: =SUMIF(PLAYERS!C:C, B36, PLAYERS!E:E) -> 0
A37: 18 | B37: Dr. Mario | C37: =VLOOKUP(B37, PLAYERS!C:E, 3, FALSE) -> #N/A | D37: =SUMIF(PLAYERS!C:C, B37, PLAYERS!E:E) -> 0
... A80: 79 | B80: Sora | C80: =VLOOKUP(B80, PLAYERS!C:E, 3, FALSE) -> #N/A | D80: =SUMIF(PLAYERS!C:C, B80, PLAYERS!E:E) -> 0

Sheet PLAYERS
A1: Rank | B1: Player | C1: Character 1 | D1: Character 2 | E1: ASISTENCIA JUGADOR | F1: GANABLE? | G1: NOTA: | H1: Column8 | I1: Column9 | J1: Column10 | K1: Column11 | L1: Column12 | M1: Column13 | N1: Column14 | O1: Column15 | P1: Column16 | Q1: Column17 | R1: Column18 | S1: Column19 | T1: Column20 | U1: Column21 | V1: Column22
A2: 1 | B2: OW / PHX | Peppa | C2: Mario | E2: 6 | F2: NO
A3: 2 | B3: Castle | C3: AEGIS | E3: 10 | F3: NO
A4: 3 | B4: TEW | iBet | C4: Wolf | E4: 24 | F4: NO
A5: 4 | B5: TEW | LÃ¶rd | C5: Ike | E5: 20 | F5: NO
A6: 5 | B6: Slade | C6: Roy | E6: 3 | F6: NO
A7: 6 | B7: TEW | LinkEa | C7: Link | E7: 5 | F7: NO
A8: 7 | B8: Diptox | C8: AEGIS | E8: 18 | F8: NO
A9: 8 | B9: PHX | Huanito | C9: Banjo & Kazooie | E9: 16 | F9: NO
A10: 9 | B10: PHX | Zoul | C10: Diddy Kong | E10: 21 | F10: NO
A11: 10 | B11: SyC | LeSoS | C11: Sonic | E11: 2 | F11: NO
A12: 11 | B12: TEW | Piporex | C12: Cloud | E12: 25 | F12: NO
A13: 12 | B13: PHX | Wakanda | C13: Terry | E13: 7 | F13: NO | G13: SOLO ASISTE A PARADOX SERIES
A14: 13 | B14: TEW | C8 | C14: Bayonetta | E14: 15 | F14: NO
A15: 14 | B15: SS | C15: Meta Knight | E15: 8 | F15: NO SE
A16: 15 | B16: TEW | Panda | C16: King K. Rool | E16: 10 | F16: NO
A17: 16 | B17: PHX | Hikarii | C17: Simon | E17: 7 | F17: NO
A18: 17 | B18: Jubaea | C18: Incineroar | E18: 5 | F18: NO
A19: 18 | B19: PHX | Kero~ | C19: Roy | E19: x12 | F19: SI
A20: 19 | B20: PHX | Eliecer | C20: Snake | E20: 20 | F20: NO
A21: 20 | B21: Tew | Necrossb | C21: R.O.B. | E21: 3 | F21: NO
A22: 21 | B22: TEW | Loba | C22: Lucario | E22: 14 | F22: NO
A23: 22 | B23: SurgicalZ | C23: ? | E23: 8 | F23: NO SE
A24: 23 | B24: Valenz | C24: R.O.B. | E24: 19 | F24: NO
A25: 24 | B25: MNK | Porroyo | C25: Pikachu | E25: 6 | F25: NO SE
A26: 25 | B26: DaeWaton | C26: Incineroar | E26: 11 | F26: NO SE
A27: 26 | B27: TEW | CR1 | C27: King K. Rool | E27: x27 | F27: SI
A28: 27 | B28: PHX | Zorkats | C28: Ganondorf | E28: x13 | F28: SI
A29: 28 | B29: TEW | Little N | C29: Terry | E29: 10 | F29: NO
A30: 29 | B30: PHX | nicoFlein | C30: Zelda | E30: 18 | F30: NO
A31: 30 | B31: WLB | SaiKora | C31: Steve/Alex | E31: 13 | F31: NO
A32: 31 | B32: CQC | Cookie | F32: NO
A33: 32 | B33: TEW | Mae | F33: NO
A34: 33 | B34: PHX | Ertiop | F34: NO SE
A35: 34 | B35: fco92DS | F35: NO
A36: 35 | B36: FSM | sk8! | F36: SI
A37: 36 | B37: SK | Al.chemyst | F37: SI
A38: 37 | B38: Coslento
A39: 38 | B39: Drim
A40: 39 | B40: Sebaibox
...

Sheet INVASORS-PLAYERS

Sheet CHARACTERS
A1: id | B1: PERSONAJE | C1: Column1 | D1: Column4 | E1: Column5 | F1: Column6 | G1: Column7 | H1: Column8 | I1: Column9 | J1: Column10 | K1: Column11 | L1: Column12 | M1: Column13 | N1: Column14 | O1: Column15 | P1: Column16 | Q1: Column17 | R1: Column18
A2: 1 | B2: Mario
A3: 2 | B3: Donkey Kong
A4: 3 | B4: Link
A5: 4 | B5: Samus
A6: 5 | B6: Yoshi
A7: 6 | B7: Kirby
A8: 7 | B8: Fox
A9: 8 | B9: Pikachu
A10: 9 | B10: Luigi
A11: 10 | B11: Ness
A12: 11 | B12: Captain Falcon
A13: 12 | B13: Jigglypuff
... A80: 79 | B80: Sora

Sheet metadata
A1: Column1 | B1: Column2 | C1: Column3 | D1: INFO | E1: Column5 | F1: Column6 | G1: Column7 | H1: Column8 | I1: Column9 | J1: Column10 | K1: Column11 | L1: Column12 | M1: Column13 | N1: Column14 | O1: Column15 | P1: Column16 | Q1: Column17 | R1: Column18 | S1: Column19 | T1: Column20 | U1: Column21 | V1: Column22 | W1: Column23
A2: CREATED | B2: 46005 | D2: % APARICION=> | F2: INVENTAMOS 30 TORNEOS USADOS PARA EL %
A3: UPDATED 1 | B3: 46017
D4: nota: los "impossible" buscar partidas en smash chile y focus
